Workbook
Name _Hlk168820753: 'ID11'!#REF!
Name _Hlk169183259: 'ID11'!#REF!

Sheet ID11
A1: TO10.01.1.D01 | B1: Cau hoi ly thuyet | C1: {=IFERROR(INDEX(Sheet2!B:B, MATCH(TRUE, LEFT(Sheet2!A:A,9)=LEFT(A1,9),0)),"")}
A2: TO10.01.1.D02 | B2: Xac dinh menh de, menh de chua bien | C2: {=IFERROR(INDEX(Sheet2!B:B, MATCH(TRUE, LEFT(Sheet2!A:A,9)=LEFT(A2,9),0)),"")}
A3: TO10.01.1.D03 | B3: Xet tinh dung sai cua mot menh de | C3: {=IFERROR(INDEX(Sheet2!B:B, MATCH(TRUE, LEFT(Sheet2!A:A,9)=LEFT(A3,9),0)),"")}
A4: TO10.01.1.D04 | B4: Phu dinh mot menh de | C4: {=IFERROR(INDEX(Sheet2!B:B, MATCH(TRUE, LEFT(Sheet2!A:A,9)=LEFT(A4,9),0)),"")}
A5: TO10.01.1.D05 | B5: Menh de keo theo, menh de dao, menh de tuong duong | C5: {=IFERROR(INDEX(Sheet2!B:B, MATCH(TRUE, LEFT(Sheet2!A:A,9)=LEFT(A5,9),0)),"")}
A6: TO10.01.1.D06 | B6: Ap dung menh de vao suy luan toan hoc | C6: {=IFERROR(INDEX(Sheet2!B:B, MATCH(TRUE, LEFT(Sheet2!A:A,9)=LEFT(A6,9),0)),"")}
A7: TO10.01.1.D07 | B7: Toan thuc te | C7: {=IFERROR(INDEX(Sheet2!B:B, MATCH(TRUE, LEFT(Sheet2!A:A,9)=LEFT(A7,9),0)),"")}
A8: TO10.01.2.D01 | B8: Cau hoi ly thuyet | C8: {=IFERROR(INDEX(Sheet2!B:B, MATCH(TRUE, LEFT(Sheet2!A:A,9)=LEFT(A8,9),0)),"")}
A9: TO10.01.2.D02 | B9: Xac dinh mot tap hop | C9: {=IFERROR(INDEX(Sheet2!B:B, MATCH(TRUE, LEFT(Sheet2!A:A,9)=LEFT(A9,9),0)),"")}
A10: TO10.01.2.D03 | B10: Cac phep toan ve giao, hop, hieu cua hai tap hop | C10: {=IFERROR(INDEX(Sheet2!B:B, MATCH(TRUE, LEFT(Sheet2!A:A,9)=LEFT(A10,9),0)),"")}
A11: TO10.01.2.D04 | B11: Tap hop con cua mot tap hop, hai tap hop bang nhau | C11: {=IFERROR(INDEX(Sheet2!B:B, MATCH(TRUE, LEFT(Sheet2!A:A,9)=LEFT(A11,9),0)),"")}
A12: TO10.01.2.D05 | B12: Toan thuc te, ung dung cua tap hop | C12: {=IFERROR(INDEX(Sheet2!B:B, MATCH(TRUE, LEFT(Sheet2!A:A,9)=LEFT(A12,9),0)),"")}
... A195: TO10.07.2.D16 | B195: Toan thuc te | C195: {=IFERROR(INDEX(Sheet2!B:B, MATCH(TRUE, LEFT(Sheet2!A:A,9)=LEFT(A195,9),0)),"")}
C196: {=IFERROR(INDEX(Sheet2!B:B, MATCH(TRUE, LEFT(Sheet2!A:A,9)=LEFT(A196,9),0)),"")} -> 0
A197: MÃ CĐ | B197: §23. Phuong trinh elip | C197: {=IFERROR(INDEX(Sheet2!B:B, MATCH(TRUE, LEFT(Sheet2!A:A,9)=LEFT(A197,9),0)),"")}
A198: TO10.07.3.D01 | B198: Cac cau hoi ly thuyet | C198: {=IFERROR(INDEX(Sheet2!B:B, MATCH(TRUE, LEFT(Sheet2!A:A,9)=LEFT(A198,9),0)),"")}
A199: TO10.07.3.D02 | B199: Nhan dang phuong trinh elip | C199: {=IFERROR(INDEX(Sheet2!B:B, MATCH(TRUE, LEFT(Sheet2!A:A,9)=LEFT(A199,9),0)),"")}
A200: TO10.07.3.D03 | B200: Xac dinh cac yeu to cua elip | C200: {=IFERROR(INDEX(Sheet2!B:B, MATCH(TRUE, LEFT(Sheet2!A:A,9)=LEFT(A200,9),0)),"")}
A201: TO10.07.3.D04 | B201: Viet phuong trinh elip | C201: {=IFERROR(INDEX(Sheet2!B:B, MATCH(TRUE, LEFT(Sheet2!A:A,9)=LEFT(A201,9),0)),"")}
A202: TO10.07.3.D05 | B202: Cac bieu thuc lien quan elip | C202: {=IFERROR(INDEX(Sheet2!B:B, MATCH(TRUE, LEFT(Sheet2!A:A,9)=LEFT(A202,9),0)),"")}
A203: TO10.07.3.D06 | B203: Tiep tuyen cua elip | C203: {=IFERROR(INDEX(Sheet2!B:B, MATCH(TRUE, LEFT(Sheet2!A:A,9)=LEFT(A203,9),0)),"")}
A204: TO10.07.3.D07 | B204: Bai toan lien quan den tuong giao cua elip | C204: {=IFERROR(INDEX(Sheet2!B:B, MATCH(TRUE, LEFT(Sheet2!A:A,9)=LEFT(A204,9),0)),"")}
A205: TO10.07.3.D08 | B205: Bai toan tong hop | C205: {=IFERROR(INDEX(Sheet2!B:B, MATCH(TRUE, LEFT(Sheet2!A:A,9)=LEFT(A205,9),0)),"")}
A206: TO10.07.3.D09 | B206: Toan thuc te | C206: {=IFERROR(INDEX(Sheet2!B:B, MATCH(TRUE, LEFT(Sheet2!A:A,9)=LEFT(A206,9),0)),"")}
A207: TO10.07.4.D01 | B207: Cac cau hoi ly thuyet | C207: {=IFERROR(INDEX(Sheet2!B:B, MATCH(TRUE, LEFT(Sheet2!A:A,9)=LEFT(A207,9),0)),"")}
A208: TO10.07.4.D02 | B208: Nhan dang phuong trinh parabol | C208: {=IFERROR(INDEX(Sheet2!B:B, MATCH(TRUE, LEFT(Sheet2!A:A,9)=LEFT(A208,9),0)),"")}
... A399: TO10.06.3.S07 | B399: Bai toan thuc te | C399: {=IFERROR(INDEX(Sheet2!B:B, MATCH(TRUE, LEFT(Sheet2!A:A,9)=LEFT(A399,9),0)),"")}
C400: {=IFERROR(INDEX(Sheet2!B:B, MATCH(TRUE, LEFT(Sheet2!A:A,9)=LEFT(A400,9),0)),"")} -> 0
A401: MÃ CĐ | B401: §19. Bat phuong trinh bac hai | C401: {=IFERROR(INDEX(Sheet2!B:B, MATCH(TRUE, LEFT(Sheet2!A:A,9)=LEFT(A401,9),0)),"")}
A402: TO10.06.4.S01 | B402: Cau hoi li thuyet | C402: {=IFERROR(INDEX(Sheet2!B:B, MATCH(TRUE, LEFT(Sheet2!A:A,9)=LEFT(A402,9),0)),"")}
A403: TO10.06.4.S02 | B403: Giai bat phuong trinh bac 2 | C403: {=IFERROR(INDEX(Sheet2!B:B, MATCH(TRUE, LEFT(Sheet2!A:A,9)=LEFT(A403,9),0)),"")}
A404: TO10.06.4.S03 | B404: Giai bat phuong trinh nho dau cua nhieu da thuc bac 1, bac 2 | C404: {=IFERROR(INDEX(Sheet2!B:B, MATCH(TRUE, LEFT(Sheet2!A:A,9)=LEFT(A404,9),0)),"")}
A405: TO10.06.4.S04 | B405: Giai he bat phuong trinh bac hai | C405: {=IFERROR(INDEX(Sheet2!B:B, MATCH(TRUE, LEFT(Sheet2!A:A,9)=LEFT(A405,9),0)),"")}
A406: TO10.06.4.S05 | B406: Tim m de phuong trinh bac 2 co nghiem thoa dieu kien | C406: {=IFERROR(INDEX(Sheet2!B:B, MATCH(TRUE, LEFT(Sheet2!A:A,9)=LEFT(A406,9),0)),"")}
A407: TO10.06.4.S06 | B407: Tim m de phuong trinh trung phuong co nghiem thoa dieu kien | C407: {=IFERROR(INDEX(Sheet2!B:B, MATCH(TRUE, LEFT(Sheet2!A:A,9)=LEFT(A407,9),0)),"")}
A408: TO10.06.4.S07 | B408: Tim m de phuong trinh bac 2 co nghiem hoac vo nghiem | C408: {=IFERROR(INDEX(Sheet2!B:B, MATCH(TRUE, LEFT(Sheet2!A:A,9)=LEFT(A408,9),0)),"")}
A409: TO10.06.4.S08 | B409: Tim m de bat phuong trinh bac 2 nghiem dung voi moi x | C409: {=IFERROR(INDEX(Sheet2!B:B, MATCH(TRUE, LEFT(Sheet2!A:A,9)=LEFT(A409,9),0)),"")}
A410: TO10.06.4.S09 | B410: Giai va bien luan bat phuong trinh bac hai | C410: {=IFERROR(INDEX(Sheet2!B:B, MATCH(TRUE, LEFT(Sheet2!A:A,9)=LEFT(A410,9),0)),"")}
A411: TO10.06.4.S10 | B411: Tim m de bat phuong trinh bac hai co nghiem hoac vo nghiem | C411: {=IFERROR(INDEX(Sheet2!B:B, MATCH(TRUE, LEFT(Sheet2!A:A,9)=LEFT(A411,9),0)),"")}
A412: TO10.06.4.S11 | B412: Tim m de he hai bat phuong trinh bac hai dung voi moi x | C412: {=IFERROR(INDEX(Sheet2!B:B, MATCH(TRUE, LEFT(Sheet2!A:A,9)=LEFT(A412,9),0)),"")}
...

Sheet Sheet2
A1: TO11.01.1 | B1: Ham so luong giac va phuong trinh luong giac/Cac cung va goc luong giac
A2: TO11.01.2 | B2: Ham so luong giac va phuong trinh luong giac/Gia tri luong giac cua mot cung
A3: TO11.01.3 | B3: Ham so luong giac va phuong trinh luong giac/Cong thuc luong giac
A4: TO11.01.4 | B4: Ham so luong giac va phuong trinh luong giac/Cac he thuc luong trong tam giac
A5: TO11.01.5 | B5: Ham so luong giac va phuong trinh luong giac/Ham so luong giac
A6: TO11.01.6 | B6: Ham so luong giac va phuong trinh luong giac/Phuong trinh luong giac
A7: TO11.02.1 | B7: To hop – Xac suat/Quy tac cong – Quy tac nhan
A8: TO11.02.2 | B8: To hop – Xac suat/Hoan vi – Chinh hop – To hop
A9: TO11.02.3 | B9: To hop – Xac suat/Nhi thuc Newton
A10: TO11.02.4 | B10: To hop – Xac suat/Xac suat
A11: TO11.03.1 | B11: Day so – Cap so cong – Cap so nhan/Day so
A12: TO11.03.2 | B12: Day so – Cap so cong – Cap so nhan/Cap so cong
... A25: TO11.06.4 | B25: Hinh hoc khong gian/Khoang cach
