Workbook
Name _Hlk168820753: 'ID12'!#REF!
Name _Hlk169183259: 'ID12'!#REF!

Sheet ID12
A1: MÃ CĐ | B1: §1. Tinh don dieu | C1: {=IFERROR(INDEX(Sheet2!B:B, MATCH(TRUE, LEFT(Sheet2!A:A,9)=LEFT(A1,9),0)),"")}
A2: TO12.01.1.D01 | B2: Cau hoi ly thuyet va tinh chat ve tinh don dieu | C2: {=IFERROR(INDEX(Sheet2!B:B, MATCH(TRUE, LEFT(Sheet2!A:A,9)=LEFT(A2,9),0)),"")} -> Ung dung dao ham de khao sat va ve do thi ham so/Tinh don dieu va cuc tri cua ham so
A3: TO12.01.1.D02 | B3: Tinh don dieu cua ham so biet cong thuc f (x) (khong GTTD) | C3: {=IFERROR(INDEX(Sheet2!B:B, MATCH(TRUE, LEFT(Sheet2!A:A,9)=LEFT(A3,9),0)),"")} -> Ung dung dao ham de khao sat va ve do thi ham so/Tinh don dieu va cuc tri cua ham so
A4: TO12.01.1.D03 | B4: Tinh don dieu cua ham so biet cac do thi | C4: {=IFERROR(INDEX(Sheet2!B:B, MATCH(TRUE, LEFT(Sheet2!A:A,9)=LEFT(A4,9),0)),"")} -> Ung dung dao ham de khao sat va ve do thi ham so/Tinh don dieu va cuc tri cua ham so
A5: TO12.01.1.D04 | B5: Tinh don dieu cua ham so biet cac BBT, BXD | C5: {=IFERROR(INDEX(Sheet2!B:B, MATCH(TRUE, LEFT(Sheet2!A:A,9)=LEFT(A5,9),0)),"")} -> Ung dung dao ham de khao sat va ve do thi ham so/Tinh don dieu va cuc tri cua ham so
A6: TO12.01.1.D05 | B6: Tinh don dieu cua ham so lien quan bieu thuc dao ham | C6: {=IFERROR(INDEX(Sheet2!B:B, MATCH(TRUE, LEFT(Sheet2!A:A,9)=LEFT(A6,9),0)),"")} -> Ung dung dao ham de khao sat va ve do thi ham so/Tinh don dieu va cuc tri cua ham so
A7: TO12.01.1.D06 | B7: Tinh don dieu cua ham h (x) = f (u) + g (x) biet cac BBT, BXD | C7: {=IFERROR(INDEX(Sheet2!B:B, MATCH(TRUE, LEFT(Sheet2!A:A,9)=LEFT(A7,9),0)),"")} -> Ung dung dao ham de khao sat va ve do thi ham so/Tinh don dieu va cuc tri cua ham so
A8: TO12.01.1.D07 | B8: Tinh don dieu cua ham lien ket h (x) = f (u) + g (x) biet cac do thi | C8: {=IFERROR(INDEX(Sheet2!B:B, MATCH(TRUE, LEFT(Sheet2!A:A,9)=LEFT(A8,9),0)),"")} -> Ung dung dao ham de khao sat va ve do thi ham so/Tinh don dieu va cuc tri cua ham so
A9: TO12.01.1.D08 | B9: Tinh don dieu cua ham g (x) khi biet do thi, BBT cua f (u) | C9: {=IFERROR(INDEX(Sheet2!B:B, MATCH(TRUE, LEFT(Sheet2!A:A,9)=LEFT(A9,9),0)),"")} -> Ung dung dao ham de khao sat va ve do thi ham so/Tinh don dieu va cuc tri cua ham so
A10: TO12.01.1.D09 | B10: Tinh don dieu cua ham so chua dau GTTD | C10: {=IFERROR(INDEX(Sheet2!B:B, MATCH(TRUE, LEFT(Sheet2!A:A,9)=LEFT(A10,9),0)),"")} -> Ung dung dao ham de khao sat va ve do thi ham so/Tinh don dieu va cuc tri cua ham so
A11: TO12.01.1.D10 | B11: Bai toan thuc te co su dung su bien thien cua ham so | C11: {=IFERROR(INDEX(Sheet2!B:B, MATCH(TRUE, LEFT(Sheet2!A:A,9)=LEFT(A11,9),0)),"")} -> Ung dung dao ham de khao sat va ve do thi ham so/Tinh don dieu va cuc tri cua ham so
A12: TO12.01.1.D11 | B12: Tim tham so de ham b1 tren b1 don dieu | C12: {=IFERROR(INDEX(Sheet2!B:B, MATCH(TRUE, LEFT(Sheet2!A:A,9)=LEFT(A12,9),0)),"")} -> Ung dung dao ham de khao sat va ve do thi ham so/Tinh don dieu va cuc tri cua ham so
... A15: TO12.01.1.D14 | B15: Tinh don dieu cua ham so chua dau GTTD co tham so biet do thi, BBT | C15: {=IFERROR(INDEX(Sheet2!B:B, MATCH(TRUE, LEFT(Sheet2!A:A,9)=LEFT(A15,9),0)),"")} -> Ung dung dao ham de khao sat va ve do thi ham so/Tinh don dieu va cuc tri cua ham so
C16: {=IFERROR(INDEX(Sheet2!B:B, MATCH(TRUE, LEFT(Sheet2!A:A,9)=LEFT(A16,9),0)),"")} -> 0
A17: MÃ CĐ | B17: §2. Cuc tri cua ham so | C17: {=IFERROR(INDEX(Sheet2!B:B, MATCH(TRUE, LEFT(Sheet2!A:A,9)=LEFT(A17,9),0)),"")}
A18: TO12.01.2.D01 | B18: Cau hoi ly thuyet va tinh chat ve cuc tri | C18: {=IFERROR(INDEX(Sheet2!B:B, MATCH(TRUE, LEFT(Sheet2!A:A,9)=LEFT(A18,9),0)),"")} -> Ung dung dao ham de khao sat va ve do thi ham so/Gia tri lon nhat va gia tri nho nhat cua ham so
A19: TO12.01.2.D02 | B19: Cuc tri cua ham so cho boi mot cong thuc (Khong GTTD) | C19: {=IFERROR(INDEX(Sheet2!B:B, MATCH(TRUE, LEFT(Sheet2!A:A,9)=LEFT(A19,9),0)),"")} -> Ung dung dao ham de khao sat va ve do thi ham so/Gia tri lon nhat va gia tri nho nhat cua ham so
A20: TO12.01.2.D03 | B20: Cuc tri cua ham so biet cac do thi (Khong GTTD) | C20: {=IFERROR(INDEX(Sheet2!B:B, MATCH(TRUE, LEFT(Sheet2!A:A,9)=LEFT(A20,9),0)),"")} -> Ung dung dao ham de khao sat va ve do thi ham so/Gia tri lon nhat va gia tri nho nhat cua ham so
A21: TO12.01.2.D04 | B21: Cuc tri cua ham so biet cac BBT, BXD so (Khong GTTD) | C21: {=IFERROR(INDEX(Sheet2!B:B, MATCH(TRUE, LEFT(Sheet2!A:A,9)=LEFT(A21,9),0)),"")} -> Ung dung dao ham de khao sat va ve do thi ham so/Gia tri lon nhat va gia tri nho nhat cua ham so
A22: TO12.01.2.D05 | B22: Cuc tri cua ham so lien quan bieu thuc dao ham (Khong GTTD) | C22: {=IFERROR(INDEX(Sheet2!B:B, MATCH(TRUE, LEFT(Sheet2!A:A,9)=LEFT(A22,9),0)),"")} -> Ung dung dao ham de khao sat va ve do thi ham so/Gia tri lon nhat va gia tri nho nhat cua ham so
A23: TO12.01.2.D06 | B23: Cuc tri cua ham lien ket h (x) = f (u) + g (x) biet cac BBT, do thi (Khong GTTD) | C23: {=IFERROR(INDEX(Sheet2!B:B, MATCH(TRUE, LEFT(Sheet2!A:A,9)=LEFT(A23,9),0)),"")} -> Ung dung dao ham de khao sat va ve do thi ham so/Gia tri lon nhat va gia tri nho nhat cua ham so
A24: TO12.01.2.D07 | B24: Cuc tri cua ham so chua dau GTTD, ham so cho boi nhieu cong thuc | C24: {=IFERROR(INDEX(Sheet2!B:B, MATCH(TRUE, LEFT(Sheet2!A:A,9)=LEFT(A24,9),0)),"")} -> Ung dung dao ham de khao sat va ve do thi ham so/Gia tri lon nhat va gia tri nho nhat cua ham so
A25: TO12.01.2.D08 | B25: Cuc tri cua ham so chua dau GTTD, ham so cho boi nhieu cong thuc khi biet do thi, BBT | C25: {=IFERROR(INDEX(Sheet2!B:B, MATCH(TRUE, LEFT(Sheet2!A:A,9)=LEFT(A25,9),0)),"")} -> Ung dung dao ham de khao sat va ve do thi ham so/Gia tri lon nhat va gia tri nho nhat cua ham so
A26: TO12.01.2.D09 | B26: Bai toan thuc te lien quan den cuc tri ham so | C26: {=IFERROR(INDEX(Sheet2!B:B, MATCH(TRUE, LEFT(Sheet2!A:A,9)=LEFT(A26,9),0)),"")} -> Ung dung dao ham de khao sat va ve do thi ham so/Gia tri lon nhat va gia tri nho nhat cua ham so
A27: TO12.01.2.D10 | B27: Tim tham so de f (x) dat cuc tri tai 1 diem x0 cho truoc (Khong GTTD) | C27: {=IFERROR(INDEX(Sheet2!B:B, MATCH(TRUE, LEFT(Sheet2!A:A,9)=LEFT(A27,9),0)),"")} -> Ung dung dao ham de khao sat va ve do thi ham so/Gia tri lon nhat va gia tri nho nhat cua ham so
A28: TO12.01.2.D11 | B28: Tim tham so de f (x) co cuc tri, khong co cuc tri (Khong GTTD) | C28: {=IFERROR(INDEX(Sheet2!B:B, MATCH(TRUE, LEFT(Sheet2!A:A,9)=LEFT(A28,9),0)),"")} -> Ung dung dao ham de khao sat va ve do thi ham so/Gia tri lon nhat va gia tri nho nhat cua ham so
... A31: TO12.01.2.D14 | B31: Tim tham so lien quan den cuc tri cua ham so khac thoa man DK (Khong GTTD) | C31: {=IFERROR(INDEX(Sheet2!B:B, MATCH(TRUE, LEFT(Sheet2!A:A,9)=LEFT(A31,9),0)),"")} -> Ung dung dao ham de khao sat va ve do thi ham so/Gia tri lon nhat va gia tri nho nhat cua ham so
C32: {=IFERROR(INDEX(Sheet2!B:B, MATCH(TRUE, LEFT(Sheet2!A:A,9)=LEFT(A32,9),0)),"")} -> 0
A33: MÃ CĐ | B33: §3. Gia tri lon nhat, gia tri nho nhat cua ham so | C33: {=IFERROR(INDEX(Sheet2!B:B, MATCH(TRUE, LEFT(Sheet2!A:A,9)=LEFT(A33,9),0)),"")}
A34: TO12.01.3.D01 | B34: Cau hoi ly thuyet ve MAX - MIN | C34: {=IFERROR(INDEX(Sheet2!B:B, MATCH(TRUE, LEFT(Sheet2!A:A,9)=LEFT(A34,9),0)),"")} -> Ung dung dao ham de khao sat va ve do thi ham so/Duong tiem can cua do thi ham so
A35: TO12.01.3.D02 | B35: GTLN, GTNN cua f (x) tren doan biet bieu thuc f (x) | C35: {=IFERROR(INDEX(Sheet2!B:B, MATCH(TRUE, LEFT(Sheet2!A:A,9)=LEFT(A35,9),0)),"")} -> Ung dung dao ham de khao sat va ve do thi ham so/Duong tiem can cua do thi ham so
A36: TO12.01.3.D03 | B36: GTLN, GTNN cua f (x) tren khoang biet bieu thuc f (x) | C36: {=IFERROR(INDEX(Sheet2!B:B, MATCH(TRUE, LEFT(Sheet2!A:A,9)=LEFT(A36,9),0)),"")} -> Ung dung dao ham de khao sat va ve do thi ham so/Duong tiem can cua do thi ham so
A37: TO12.01.3.D04 | B37: GTLN, GTNN cua ham so g (x) biet cac BBT, do thi | C37: {=IFERROR(INDEX(Sheet2!B:B, MATCH(TRUE, LEFT(Sheet2!A:A,9)=LEFT(A37,9),0)),"")} -> Ung dung dao ham de khao sat va ve do thi ham so/Duong tiem can cua do thi ham so
A38: TO12.01.3.D05 | B38: GTLN, GTNN cua ham so bang PP dat an phu | C38: {=IFERROR(INDEX(Sheet2!B:B, MATCH(TRUE, LEFT(Sheet2!A:A,9)=LEFT(A38,9),0)),"")} -> Ung dung dao ham de khao sat va ve do thi ham so/Duong tiem can cua do thi ham so
A39: TO12.01.3.D06 | B39: Su dung cac danh gia, BDT co dien cho ham mot bien | C39: {=IFERROR(INDEX(Sheet2!B:B, MATCH(TRUE, LEFT(Sheet2!A:A,9)=LEFT(A39,9),0)),"")} -> Ung dung dao ham de khao sat va ve do thi ham so/Duong tiem can cua do thi ham so
A40: TO12.01.3.D07 | B40: GTLN, GTNN lien quan ham so hop g (f (x)), f (u (x)), … khi biet cac do thi, BBT | C40: {=IFERROR(INDEX(Sheet2!B:B, MATCH(TRUE, LEFT(Sheet2!A:A,9)=LEFT(A40,9),0)),"")} -> Ung dung dao ham de khao sat va ve do thi ham so/Duong tiem can cua do thi ham so
A41: TO12.01.3.D08 | B41: GTLN, GTNN cua ham so chua dau GTTD | C41: {=IFERROR(INDEX(Sheet2!B:B, MATCH(TRUE, LEFT(Sheet2!A:A,9)=LEFT(A41,9),0)),"")} -> Ung dung dao ham de khao sat va ve do thi ham so/Duong tiem can cua do thi ham so
A42: TO12.01.3.D09 | B42: Bai toan thuc te lien quan den GTLN-GTNN | C42: {=IFERROR(INDEX(Sheet2!B:B, MATCH(TRUE, LEFT(Sheet2!A:A,9)=LEFT(A42,9),0)),"")} -> Ung dung dao ham de khao sat va ve do thi ham so/Duong tiem can cua do thi ham so
A43: TO12.01.3.D10 | B43: Tim m de hs f (x) co GTLN, GTNN thoa man dk cho truoc | C43: {=IFERROR(INDEX(Sheet2!B:B, MATCH(TRUE, LEFT(Sheet2!A:A,9)=LEFT(A43,9),0)),"")} -> Ung dung dao ham de khao sat va ve do thi ham so/Duong tiem can cua do thi ham so
A44: TO12.01.3.D11 | B44: Tim tham so de hs chua dau GTTD, ham hop, ham lien ket co GTLN, GTNN thoa man dk cho truoc | C44: {=IFERROR(INDEX(Sheet2!B:B, MATCH(TRUE, LEFT(Sheet2!A:A,9)=LEFT(A44,9),0)),"")} -> Ung dung dao ham de khao sat va ve do thi ham so/Duong tiem can cua do thi ham so
...

Sheet Sheet2
A1: TO12.01.1 | B1: Ung dung dao ham de khao sat va ve do thi ham so/Tinh don dieu va cuc tri cua ham so
A2: TO12.01.2 | B2: Ung dung dao ham de khao sat va ve do thi ham so/Gia tri lon nhat va gia tri nho nhat cua ham so
A3: TO12.01.3 | B3: Ung dung dao ham de khao sat va ve do thi ham so/Duong tiem can cua do thi ham so
A4: TO12.01.4 | B4: Ung dung dao ham de khao sat va ve do thi ham so/Khao sat su bien thien va ve do thi cua ham so
A5: TO12.01.5 | B5: Ung dung dao ham de khao sat va ve do thi ham so/Ung dung dao ham de giai quyet mot so van de thuc tien
A6: TO12.02.1 | B6: Vecto va he truc toa do trong khong gian/Vecto trong khong gian
A7: TO12.02.2 | B7: Vecto va he truc toa do trong khong gian/He truc toa do trong khong gian
A8: TO12.02.3 | B8: Vecto va he truc toa do trong khong gian/Bieu thuc toa do cua cac phep toan vecto
A9: TO12.03.1 | B9: Cac so dac trung do muc do phan tan cua mau so lieu ghep nhom/Khoang bien thien va khoang tu phan vi
A10: TO12.03.2 | B10: Cac so dac trung do muc do phan tan cua mau so lieu ghep nhom/Phuong sai va do lech chuan
A11: TO12.04.1 | B11: Nguyen ham va tich phan/Nguyen ham
A12: TO12.04.2 | B12: Nguyen ham va tich phan/Tich phan
... A19: TO12.06.2 | B19: Xac suat co dieu kien/Cong thuc xac suat toan phan va cong thuc Bayes
